Workbook

Sheet 00 Core Canvas
A1: CORE STRATEGY CANVAS – GIỌT LÀNH MỖI SÁNG
A2: Bản core để toàn brand theo dõi chiến lược Membership F&B: Thẻ Giọt Lành An Nhiên + Thẻ Ban Mai
A4: 1. Định vị | E4: 2. Big Idea | I4: 3. Mô hình
A5: Healthy lifestyle tiện lợi, an lành và có gu cho người bận rộn. Không bán rẻ; bán đặc quyền và thói quen ban mai. | E5: Giọt Lành Mỗi Sáng – một giọt lành nhỏ cho ngày mới an nhiên, dễ duy trì và không cần phức tạp. | I5: B2B2C qua Leader/KOC, văn phòng, studio yoga/pilates, spa/salon và các điểm gom đơn buổi sáng.
A9: 4. Sản phẩm mồi | E9: 5. Sản phẩm upsell | I9: 6. 3 vị sữa hạt
A10: Thẻ Giọt Lành An Nhiên: 199K mở thẻ, sữa hạt signature 15K/chai, tối đa 3 chai/ngày. | E10: Thẻ Ban Mai: 249K mở thẻ, set bữa sáng Ban Mai 60K gồm trà, sữa hạt, ginger shot, gạo lứt, topping và trứng. | I10: Mộc Mè – Lạc Hương – Mộc Đậu. Menu dùng tên thương hiệu; tem/FAQ vẫn minh bạch thành phần mè, lạc, đậu nành.
A14: 7. Khách hàng lõi | E14: 8. Chiến lược phễu | I14: 9. Kênh chính
A15: Nữ văn phòng 22–40, người bận rộn, khách wellness, nhóm văn phòng đặt sáng, người mới bắt đầu healthy. | E15: Awareness → Trial → Membership → Habit → Upsell Ban Mai → Retention → Referral/Advocacy. | I15: Leader/KOC + group order văn phòng/studio/spa là kênh chính. Ads chỉ chạy sau khi có feedback và nội dung thật.
A19: 10. KPI pilot 30 ngày | E19: 11. Nguyên tắc vận hành | I19: 12. Rủi ro cần khóa
A20: 300–500 thẻ Giọt Lành; 100–150 thẻ Ban Mai; 20–30 Leader; ≥60% hội viên dùng thẻ trong 7 ngày đầu. | E20: Ban Mai cần pre-order trước 21h; sữa tracking theo SĐT/QR; forecast theo active rate; kiểm soát cost/chai ≤9–10K. | I20: Không dùng claim chữa bệnh/giảm cân thần kỳ; không gọi 'rẻ nhất'; không giấu dị ứng; không để 1–3 trà trong set chính.
A24: NORTH STAR: Không bán một món uống. Bán một thói quen ban mai an lành, tiện và có gu.

Sheet 01 Offer Pricing
A1: OFFER & PRICING CANVAS
A2: Chốt sản phẩm, quyền lợi, giá, cost mục tiêu và các biến số để toàn workbook tham chiếu
A4: Biến số vận hành | B4: Giá trị | C4: Ghi chú
A5: Giá thẻ Giọt Lành An Nhiên | B5: 199000 | C5: Phí mở đặc quyền sữa hạt
A6: Giá thẻ Ban Mai | B6: 249000 | C6: Phí mở đặc quyền bữa sáng
A7: Giá sữa hội viên/chai | B7: 15000 | C7: Áp dụng 3 vị signature
A8: Giá set Ban Mai hội viên | B8: 60000 | C8: Set tiêu chuẩn
A9: Cost mục tiêu sữa/chai | B9: 9000 | C9: Bao gồm nguyên liệu, chai, tem, hao hụt cơ bản
A10: Cost mục tiêu set Ban Mai | B10: 45000 | C10: Tổng cost mục tiêu để giữ biên
A11: Hoa hồng thẻ Giọt Lành | B11: 50000 | C11: Có thể điều chỉnh 40–50K
A12: Hoa hồng thẻ Ban Mai | B12: 60000 | C12: Có thể điều chỉnh 50–60K
A13: Giới hạn sữa/ngày/hội viên | B13: 3 | C13: Không chuyển nhượng tự do
A14: Target thẻ Giọt Lành 30D | B14: 300 | C14: Pilot 30 ngày
A15: Target thẻ Ban Mai 30D | B15: 50 | C15: Pilot 30 ngày
A16: Target chai sữa 30D | B16: 4500 | C16: Pilot 30 ngày
A17: Target set Ban Mai 30D | B17: 600 | C17: Pilot 30 ngày
A18: Target doanh thu pilot | B18: =B14*B5+B15*B6+B16*B7+B17*B8 -> 175650000 | C18: Tự tính theo target
A19: Target giao đúng giờ | B19: 0.9 | C19: Mục tiêu vận hành
A22: Membership | B22: Giá thẻ | C22: Quyền lợi chính | D22: Giá hội viên | E22: Giới hạn | F22: Vai trò trong phễu | G22: Ghi chú vận hành
A23: Thẻ Giọt Lành An Nhiên | B23: 199000 | C23: Mua sữa hạt signature | D23: 15K/chai | E23: Tối đa 3 chai/ngày | F23: Sản phẩm mồi, kéo khách mới, tạo thói quen | G23: Gắn với SĐT/QR, không cộng dồn ưu đãi
A24: Thẻ Ban Mai | B24: 249000 | C24: Mua set bữa sáng Ban Mai | D24: 60K/set | E24: Ưu tiên đặt trước 21h hôm trước | F24: Upsell, tăng giá trị đơn hàng, hợp group order | G24: Set tiêu chuẩn gồm 1 trà; trà thêm mua ưu đãi riêng
A28: Tên menu | B28: Thành phần chính | C28: Mô tả thương hiệu | D28: Use case | E28: Ghi chú nhãn/FAQ
A29: Mộc Mè | B29: Mè | C29: Vị thanh bùi, mộc, nhẹ bụng, hợp buổi sáng. | D29: Khách thích vị thanh, nhẹ | E29: Ghi rõ mè trên tem để minh bạch dị ứng
A30: Lạc Hương | B30: Lạc | C30: Hương thơm ấm, béo nhẹ, dễ uống, phù hợp người thích vị đậm. | D30: Khách thích vị béo, thơm | E30: Ghi rõ lạc trên tem để minh bạch dị ứng
A31: Mộc Đậu | B31: Đậu nành | C31: Vị mộc, quen thuộc, êm, dễ dùng mỗi ngày. | D31: Khách mới bắt đầu healthy | E31: Ghi rõ đậu nành trên tem để minh bạch dị ứng
A35: Dòng doanh thu | B35: Giá bán/đơn vị | C35: Cost mục tiêu | D35: Biên gộp/đơn vị | E35: Biên gộp % | F35: Hoa hồng Leader | G35: Net còn lại sau HH | H35: Ghi chú
A36: Sữa hạt/chai | B36: =$B$7 -> 15000 | C36: =$B$9 -> 9000 | D36: =B36-C36 -> 6000 | E36: =IFERROR(D36/B36,0) -> 0.4 | F36: 0 | G36: =D36-F36 -> 6000 | H36: Công thức lấy từ biến số vận hành
A37: Set Ban Mai | B37: =$B$8 -> 60000 | C37: =$B$10 -> 45000 | D37: =B37-C37 -> 15000 | E37: =IFERROR(D37/B37,0) -> 0.25 | F37: 0 | G37: =D37-F37 -> 15000 | H37: Giữ set tiêu chuẩn để không vỡ cost
A38: Thẻ Giọt Lành An Nhiên | B38: =$B$5 -> 199000 | C38: 0 | D38: =B38-C38 -> 199000 | E38: =IFERROR(D38/B38,0) -> 1 | F38: =$B$11 -> 50000 | G38: =D38-F38 -> 149000 | H38: Tiền thẻ tạo cashflow và trả CAC leader
A39: Thẻ Ban Mai | B39: =$B$6 -> 249000 | C39: 0 | D39: =B39-C39 -> 249000 | E39: =IFERROR(D39/B39,0) -> 1 | F39: =$B$12 -> 60000 | G39: =D39-F39 -> 189000 | H39: Ưu tiên upsell sau khi khách dùng sữa 3–5 lần
A41: Nguyên tắc chốt: 15K/chai là giá đặc quyền hội viên, không phải chiến lược bán rẻ. Thẻ Ban Mai cần giữ set tiêu chuẩn 1 chai trà; nếu muốn thêm trà, bán bằng ưu đãi riêng để bảo vệ biên lợi nhuận.

Sheet 02 Funnel GTM
A1: FUNNEL & GO-TO-MARKET CANVAS
A2: Phễu triển khai từ nhận diện đến membership, upsell và referral
A4: Giai đoạn | B4: Mục tiêu | C4: Hành động chính | D4: Offer chính | E4: Kênh | F4: Owner đề xuất | G4: KPI chính | H4: Trạng thái | I4: Ghi chú
A5: 1. Awareness | B5: Khách biết có đặc quyền mới | C5: Leader/KOC đăng teaser; story menu; video ngắn 'sữa hạt 15K là gì?' | D5: Thẻ Giọt Lành An Nhiên | E5: Leader, fanpage, TikTok/Reels | F5: Marketing Lead | G5: Reach, inbox, lead | H5: Chưa bắt đầu | I5: Không dùng ngôn ngữ rẻ nhất
A6: 2. Trial | B6: Khách thử vị và tin sản phẩm | C6: Tasting 3 vị; sample cho Leader mạnh; voucher chai đầu | D6: Mộc Mè, Lạc Hương, Mộc Đậu | E6: Văn phòng, studio, spa | F6: Sales/Leader Lead | G6: Tỷ lệ thử → mua thẻ | H6: Chưa bắt đầu | I6: Lấy feedback thật
A7: 3. Membership | B7: Bán thẻ 199K | C7: Chốt bằng script: 199K mở thẻ, sữa 15K/chai | D7: Thẻ Giọt Lành An Nhiên | E7: Inbox, QR, leader code | F7: Sales Lead | G7: Số thẻ bán/ngày | H7: Chưa bắt đầu | I7: Tracking theo SĐT/QR
A8: 4. Habit | B8: Khách dùng đều trong 7 ngày đầu | C8: Menu hằng ngày; nhắc lịch; challenge 7–21 ngày | D8: Sữa hạt 15K | E8: Zalo, story, CRM | F8: CRM/Ops | G8: Tỷ lệ active 7D | H8: Chưa bắt đầu | I8: Ưu tiên trải nghiệm lần đầu
A9: 5. Upsell | B9: Tăng AOV từ 15K lên 60K | C9: Sau 3–5 lần mua sữa, mời thử/nâng cấp Ban Mai | D9: Thẻ Ban Mai | E9: CRM, leader, group order | F9: Sales Lead | G9: Tỷ lệ nâng cấp | H9: Chưa bắt đầu | I9: Không upsell quá sớm
A10: 6. Retention | B10: Giữ khách lâu dài | C10: Combo tuần; menu mới; feedback; ưu đãi nâng cấp | D10: Ban Mai, ginger shot, trà, hũ mạch | E10: CRM, cộng đồng hội viên | F10: CRM Lead | G10: Active 30D, repeat rate | H10: Chưa bắt đầu | I10: Theo dõi vị yêu thích
A11: 7. Advocacy | B11: Khách giới thiệu khách mới | C11: Referral: giới thiệu bạn mở thẻ nhận voucher/nâng cấp | D11: Cả 2 thẻ | E11: Referral code, leader | F11: Marketing/Sales | G11: Referral rate | H11: Chưa bắt đầu | I11: Không tặng free quá nhiều

Sheet 03 Leader B2B2C
A1: LEADER / B2B2C CANVAS
A2: Quản trị mạng lưới Leader, chính sách hoa hồng và tracker doanh số
A4: Nhóm Leader | B4: Lý do phù hợp | C4: Sản phẩm nên bán | D4: Cách kích hoạt
A5: Giáo viên yoga/pilates/gym | B5: Có cộng đồng quan tâm sức khỏe | C5: Giọt Lành, Ban Mai, ginger shot | D5: Tasting sau buổi tập, QR mở thẻ
A6: Admin/HR văn phòng | B6: Có nhóm đặt bữa sáng | C6: Ban Mai, group order | D6: Điểm gom đơn buổi sáng
A7: Chủ spa/salon | B7: Tệp nữ thích chăm sóc bản thân | C7: Giọt Lành, Ban Mai | D7: Đặt sample/voucher tại quầy
A8: KOC lifestyle địa phương | B8: Tạo niềm tin gần gũi | C8: Cả 2 thẻ | D8: Review 7 ngày dùng sữa
A9: Chủ shop beauty/thời trang | B9: Có khách nữ, dễ gắn lifestyle | C9: Giọt Lành | D9: Quà tặng khách thân thiết
A10: Cộng đồng mẹ/bếp sạch | B10: Quan tâm nguyên liệu và bữa sáng | C10: Ban Mai, sữa hạt | D10: Nội dung minh bạch nguyên liệu
A13: Sản phẩm | B13: Giá bán | C13: Hoa hồng Leader | D13: Ghi chú
A14: Thẻ Giọt Lành An Nhiên | B14: 199000 | C14: 50000 | D14: Giữ dưới 25% giá thẻ nếu có thể
A15: Thẻ Ban Mai | B15: 249000 | C15: 60000 | D15: Ưu tiên leader có group order
A16: Đơn Ban Mai nhóm | B16: 60000 | C16: 5000 | D16: Nếu Leader gom đơn theo điểm
A17: Mốc 20 thẻ/tuần | C17: 500000 | D17: Bonus tùy budget
A18: Mốc 50 thẻ/tháng | C18: 1500000 | D18: Bonus cho Leader mạnh
A23: Mã Leader | B23: Tên/Đối tác | C23: Nhóm | D23: Kênh chính | E23: Thẻ Giọt Lành | F23: Thẻ Ban Mai | G23: Doanh thu thẻ | H23: Hoa hồng | I23: Trạng thái | J23: Ghi chú
A24: L01 | E24: 0 | F24: 0 | G24: =E24*'01 Offer Pricing'!$B$5+F24*'01 Offer Pricing'!$B$6 -> 0 | H24: =E24*'01 Offer Pricing'!$B$11+F24*'01 Offer Pricing'!$B$12 -> 0 | I24: Chưa bắt đầu
A25: L02 | E25: 0 | F25: 0 | G25: =E25*'01 Offer Pricing'!$B$5+F25*'01 Offer Pricing'!$B$6 -> 0 | H25: =E25*'01 Offer Pricing'!$B$11+F25*'01 Offer Pricing'!$B$12 -> 0 | I25: Chưa bắt đầu
A26: L03 | E26: 0 | F26: 0 | G26: =E26*'01 Offer Pricing'!$B$5+F26*'01 Offer Pricing'!$B$6 -> 0 | H26: =E26*'01 Offer Pricing'!$B$11+F26*'01 Offer Pricing'!$B$12 -> 0 | I26: Chưa bắt đầu
A27: L04 | E27: 0 | F27: 0 | G27: =E27*'01 Offer Pricing'!$B$5+F27*'01 Offer Pricing'!$B$6 -> 0 | H27: =E27*'01 Offer Pricing'!$B$11+F27*'01 Offer Pricing'!$B$12 -> 0 | I27: Chưa bắt đầu
A28: L05 | E28: 0 | F28: 0 | G28: =E28*'01 Offer Pricing'!$B$5+F28*'01 Offer Pricing'!$B$6 -> 0 | H28: =E28*'01 Offer Pricing'!$B$11+F28*'01 Offer Pricing'!$B$12 -> 0 | I28: Chưa bắt đầu
A29: L06 | E29: 0 | F29: 0 | G29: =E29*'01 Offer Pricing'!$B$5+F29*'01 Offer Pricing'!$B$6 -> 0 | H29: =E29*'01 Offer Pricing'!$B$11+F29*'01 Offer Pricing'!$B$12 -> 0 | I29: Chưa bắt đầu
A30: L07 | E30: 0 | F30: 0 | G30: =E30*'01 Offer Pricing'!$B$5+F30*'01 Offer Pricing'!$B$6 -> 0 | H30: =E30*'01 Offer Pricing'!$B$11+F30*'01 Offer Pricing'!$B$12 -> 0 | I30: Chưa bắt đầu
A31: L08 | E31: 0 | F31: 0 | G31: =E31*'01 Offer Pricing'!$B$5+F31*'01 Offer Pricing'!$B$6 -> 0 | H31: =E31*'01 Offer Pricing'!$B$11+F31*'01 Offer Pricing'!$B$12 -> 0 | I31: Chưa bắt đầu
A32: L09 | E32: 0 | F32: 0 | G32: =E32*'01 Offer Pricing'!$B$5+F32*'01 Offer Pricing'!$B$6 -> 0 | H32: =E32*'01 Offer Pricing'!$B$11+F32*'01 Offer Pricing'!$B$12 -> 0 | I32: Chưa bắt đầu
A33: L10 | E33: 0 | F33: 0 | G33: =E33*'01 Offer Pricing'!$B$5+F33*'01 Offer Pricing'!$B$6 -> 0 | H33: =E33*'01 Offer Pricing'!$B$11+F33*'01 Offer Pricing'!$B$12 -> 0 | I33: Chưa bắt đầu
A34: L11 | E34: 0 | F34: 0 | G34: =E34*'01 Offer Pricing'!$B$5+F34*'01 Offer Pricing'!$B$6 -> 0 | H34: =E34*'01 Offer Pricing'!$B$11+F34*'01 Offer Pricing'!$B$12 -> 0 | I34: Chưa bắt đầu
A35: L12 | E35: 0 | F35: 0 | G35: =E35*'01 Offer Pricing'!$B$5+F35*'01 Offer Pricing'!$B$6 -> 0 | H35: =E35*'01 Offer Pricing'!$B$11+F35*'01 Offer Pricing'!$B$12 -> 0 | I35: Chưa bắt đầu
... A53: L30 | E53: 0 | F53: 0 | G53: =E53*'01 Offer Pricing'!$B$5+F53*'01 Offer Pricing'!$B$6 -> 0 | H53: =E53*'01 Offer Pricing'!$B$11+F53*'01 Offer Pricing'!$B$12 -> 0 | I53: Chưa bắt đầu

Sheet 04 Marketing 30D
A1: 30-DAY MARKETING EXECUTION CANVAS
A2: Lịch triển khai nội dung, kênh, owner, trạng thái và KPI cho chiến dịch launch
A4: Ngày | B4: Giai đoạn | C4: Trụ cột | D4: Nội dung triển khai | E4: Kênh | F4: Owner | G4: Trạng thái | H4: KPI đích | I4: Kết quả | J4: Ghi chú
A5: 1 | B5: Pre-launch | C5: Teaser | D5: Nếu mỗi sáng có một chai sữa hạt lành chỉ 15K, bạn có muốn duy trì không? | E5: Story/Reels/Leader | G5: Chưa bắt đầu
A6: 2 | B6: Pre-launch | C6: Offer | D6: Giới thiệu Thẻ Giọt Lành An Nhiên và quyền lợi hội viên. | E6: Fanpage/Zalo/Leader | G6: Chưa bắt đầu
A7: 3 | B7: Pre-launch | C7: Product | D7: Giới thiệu 3 vị signature: Mộc Mè, Lạc Hương, Mộc Đậu. | E7: Reels/TikTok | G7: Chưa bắt đầu
A8: 4 | B8: Pre-launch | C8: Tasting | D8: Leader dùng thử và chia sẻ cảm nhận thật. | E8: Leader story | G8: Chưa bắt đầu
A9: 5 | B9: Pre-launch | C9: Founder | D9: Mở danh sách Founding Members giới hạn. | E9: Form/QR | G9: Chưa bắt đầu
A10: 6 | B10: Launch | C10: Offer | D10: Mở bán chính thức Thẻ Giọt Lành An Nhiên. | E10: All channels | G10: Chưa bắt đầu
A11: 7 | B11: Launch | C11: BTS | D11: Video chuẩn bị sữa, đóng chai, giao sáng. | E11: Reels/TikTok | G11: Chưa bắt đầu
A12: 8 | B12: Launch | C12: Feedback | D12: Feedback khách/leader sau 1–2 ngày dùng sữa. | E12: Story/Fanpage | G12: Chưa bắt đầu
A13: 9 | B13: Launch | C13: Habit | D13: Challenge 7 ngày Giọt Lành. | E13: Zalo/Story | G13: Chưa bắt đầu
A14: 10 | B14: Launch | C14: Menu | D14: Menu ngày: vị sữa, trà, topping. | E14: Zalo/Story | G14: Chưa bắt đầu
A15: 11 | B15: Launch | C15: Education | D15: 15K là đặc quyền hội viên, không phải sale rẻ. | E15: Post | G15: Chưa bắt đầu
A16: 12 | B16: Launch | C16: Social Proof | D16: Ảnh khách nhận sữa tại văn phòng/studio. | E16: Story/Reels | G16: Chưa bắt đầu
... A34: 30 | B34: Review | C34: Tổng kết | D34: Tổng kết 30 ngày: số thẻ, số chai, feedback, next wave. | E34: Fanpage/Internal | G34: Chưa bắt đầu

Sheet 05 Ops Tracker
A1: DAILY OPS & REVENUE TRACKER
A2: Nhập số vận hành hằng ngày; doanh thu/cost/lợi nhuận gộp tự tính theo biến số ở Offer Pricing. Có thể đổi cột Ngày theo ngày launch thực tế.
A4: Ngày | B4: Thứ | C4: Thẻ Giọt Lành | D4: Thẻ Ban Mai | E4: Chai Mộc Mè | F4: Chai Lạc Hương | G4: Chai Mộc Đậu | H4: Tổng chai | I4: Set Ban Mai | J4: DT thẻ | K4: DT sữa | L4: DT Ban Mai | M4: Tổng DT | N4: Cost sữa | O4: Cost Ban Mai | P4: HH Leader | Q4: LN gộp ước tính | R4: Hàng dư/hủy | S4: Đúng giờ % | T4: Khiếu nại | U4: Ghi chú
A5: 46160 | B5: Thứ 2 | C5: 0 | D5: 0 | E5: 0 | F5: 0 | G5: 0 | H5: 0 | I5: 0 | J5: =C5*'01 Offer Pricing'!$B$5+D5*'01 Offer Pricing'!$B$6 -> 0 | K5: =H5*'01 Offer Pricing'!$B$7 -> 0 | L5: =I5*'01 Offer Pricing'!$B$8 -> 0 | M5: =SUM(J5:L5) -> 0 | N5: =H5*'01 Offer Pricing'!$B$9 -> 0 | O5: =I5*'01 Offer Pricing'!$B$10 -> 0 | P5: =C5*'01 Offer Pricing'!$B$11+D5*'01 Offer Pricing'!$B$12 -> 0 | Q5: =M5-N5-O5-P5 -> 0 | R5: 0 | S5: 0.9 | T5: 0
A6: 46161 | B6: Thứ 3 | C6: 0 | D6: 0 | E6: 0 | F6: 0 | G6: 0 | H6: 0 | I6: 0 | J6: =C6*'01 Offer Pricing'!$B$5+D6*'01 Offer Pricing'!$B$6 -> 0 | K6: =H6*'01 Offer Pricing'!$B$7 -> 0 | L6: =I6*'01 Offer Pricing'!$B$8 -> 0 | M6: =SUM(J6:L6) -> 0 | N6: =H6*'01 Offer Pricing'!$B$9 -> 0 | O6: =I6*'01 Offer Pricing'!$B$10 -> 0 | P6: =C6*'01 Offer Pricing'!$B$11+D6*'01 Offer Pricing'!$B$12 -> 0 | Q6: =M6-N6-O6-P6 -> 0 | R6: 0 | S6: 0.9 | T6: 0
A7: 46162 | B7: Thứ 4 | C7: 0 | D7: 0 | E7: 0 | F7: 0 | G7: 0 | H7: =SUM(E7:G7) -> 0 | I7: 0 | J7: =C7*'01 Offer Pricing'!$B$5+D7*'01 Offer Pricing'!$B$6 -> 0 | K7: =H7*'01 Offer Pricing'!$B$7 -> 0 | L7: =I7*'01 Offer Pricing'!$B$8 -> 0 | M7: =SUM(J7:L7) -> 0 | N7: =H7*'01 Offer Pricing'!$B$9 -> 0 | O7: =I7*'01 Offer Pricing'!$B$10 -> 0 | P7: =C7*'01 Offer Pricing'!$B$11+D7*'01 Offer Pricing'!$B$12 -> 0 | Q7: =M7-N7-O7-P7 -> 0 | R7: 0 | S7: 0.9 | T7: 0
A8: 46163 | B8: Thứ 5 | C8: 0 | D8: 0 | E8: 0 | F8: 0 | G8: 0 | H8: =SUM(E8:G8) -> 0 | I8: 0 | J8: =C8*'01 Offer Pricing'!$B$5+D8*'01 Offer Pricing'!$B$6 -> 0 | K8: =H8*'01 Offer Pricing'!$B$7 -> 0 | L8: =I8*'01 Offer Pricing'!$B$8 -> 0 | M8: =SUM(J8:L8) -> 0 | N8: =H8*'01 Offer Pricing'!$B$9 -> 0 | O8: =I8*'01 Offer Pricing'!$B$10 -> 0 | P8: =C8*'01 Offer Pricing'!$B$11+D8*'01 Offer Pricing'!$B$12 -> 0 | Q8: =M8-N8-O8-P8 -> 0 | R8: 0 | S8: 0.9 | T8: 0
A9: 46164 | B9: Thứ 6 | C9: 0 | D9: 0 | E9: 0 | F9: 0 | G9: 0 | H9: =SUM(E9:G9) -> 0 | I9: 0 | J9: =C9*'01 Offer Pricing'!$B$5+D9*'01 Offer Pricing'!$B$6 -> 0 | K9: =H9*'01 Offer Pricing'!$B$7 -> 0 | L9: =I9*'01 Offer Pricing'!$B$8 -> 0 | M9: =SUM(J9:L9) -> 0 | N9: =H9*'01 Offer Pricing'!$B$9 -> 0 | O9: =I9*'01 Offer Pricing'!$B$10 -> 0 | P9: =C9*'01 Offer Pricing'!$B$11+D9*'01 Offer Pricing'!$B$12 -> 0 | Q9: =M9-N9-O9-P9 -> 0 | R9: 0 | S9: 0.9 | T9: 0
A10: 46165 | B10: Thứ 7 | C10: 0 | D10: 0 | E10: 0 | F10: 0 | G10: 0 | H10: =SUM(E10:G10) -> 0 | I10: 0 | J10: =C10*'01 Offer Pricing'!$B$5+D10*'01 Offer Pricing'!$B$6 -> 0 | K10: =H10*'01 Offer Pricing'!$B$7 -> 0 | L10: =I10*'01 Offer Pricing'!$B$8 -> 0 | M10: =SUM(J10:L10) -> 0 | N10: =H10*'01 Offer Pricing'!$B$9 -> 0 | O10: =I10*'01 Offer Pricing'!$B$10 -> 0 | P10: =C10*'01 Offer Pricing'!$B$11+D10*'01 Offer Pricing'!$B$12 -> 0 | Q10: =M10-N10-O10-P10 -> 0 | R10: 0 | S10: 0.9 | T10: 0
A11: 46166 | B11: CN | C11: 0 | D11: 0 | E11: 0 | F11: 0 | G11: 0 | H11: =SUM(E11:G11) -> 0 | I11: 0 | J11: =C11*'01 Offer Pricing'!$B$5+D11*'01 Offer Pricing'!$B$6 -> 0 | K11: =H11*'01 Offer Pricing'!$B$7 -> 0 | L11: =I11*'01 Offer Pricing'!$B$8 -> 0 | M11: =SUM(J11:L11) -> 0 | N11: =H11*'01 Offer Pricing'!$B$9 -> 0 | O11: =I11*'01 Offer Pricing'!$B$10 -> 0 | P11: =C11*'01 Offer Pricing'!$B$11+D11*'01 Offer Pricing'!$B$12 -> 0 | Q11: =M11-N11-O11-P11 -> 0 | R11: 0 | S11: 0.9 | T11: 0
A12: 46167 | B12: Thứ 2 | C12: 0 | D12: 0 | E12: 0 | F12: 0 | G12: 0 | H12: =SUM(E12:G12) -> 0 | I12: 0 | J12: =C12*'01 Offer Pricing'!$B$5+D12*'01 Offer Pricing'!$B$6 -> 0 | K12: =H12*'01 Offer Pricing'!$B$7 -> 0 | L12: =I12*'01 Offer Pricing'!$B$8 -> 0 | M12: =SUM(J12:L12) -> 0 | N12: =H12*'01 Offer Pricing'!$B$9 -> 0 | O12: =I12*'01 Offer Pricing'!$B$10 -> 0 | P12: =C12*'01 Offer Pricing'!$B$11+D12*'01 Offer Pricing'!$B$12 -> 0 | Q12: =M12-N12-O12-P12 -> 0 | R12: 0 | S12: 0.9 | T12: 0
A13: 46168 | B13: Thứ 3 | C13: 0 | D13: 0 | E13: 0 | F13: 0 | G13: 0 | H13: =SUM(E13:G13) -> 0 | I13: 0 | J13: =C13*'01 Offer Pricing'!$B$5+D13*'01 Offer Pricing'!$B$6 -> 0 | K13: =H13*'01 Offer Pricing'!$B$7 -> 0 | L13: =I13*'01 Offer Pricing'!$B$8 -> 0 | M13: =SUM(J13:L13) -> 0 | N13: =H13*'01 Offer Pricing'!$B$9 -> 0 | O13: =I13*'01 Offer Pricing'!$B$10 -> 0 | P13: =C13*'01 Offer Pricing'!$B$11+D13*'01 Offer Pricing'!$B$12 -> 0 | Q13: =M13-N13-O13-P13 -> 0 | R13: 0 | S13: 0.9 | T13: 0
A14: 46169 | B14: Thứ 4 | C14: 0 | D14: 0 | E14: 0 | F14: 0 | G14: 0 | H14: =SUM(E14:G14) -> 0 | I14: 0 | J14: =C14*'01 Offer Pricing'!$B$5+D14*'01 Offer Pricing'!$B$6 -> 0 | K14: =H14*'01 Offer Pricing'!$B$7 -> 0 | L14: =I14*'01 Offer Pricing'!$B$8 -> 0 | M14: =SUM(J14:L14) -> 0 | N14: =H14*'01 Offer Pricing'!$B$9 -> 0 | O14: =I14*'01 Offer Pricing'!$B$10 -> 0 | P14: =C14*'01 Offer Pricing'!$B$11+D14*'01 Offer Pricing'!$B$12 -> 0 | Q14: =M14-N14-O14-P14 -> 0 | R14: 0 | S14: 0.9 | T14: 0
A15: 46170 | B15: Thứ 5 | C15: 0 | D15: 0 | E15: 0 | F15: 0 | G15: 0 | H15: =SUM(E15:G15) -> 0 | I15: 0 | J15: =C15*'01 Offer Pricing'!$B$5+D15*'01 Offer Pricing'!$B$6 -> 0 | K15: =H15*'01 Offer Pricing'!$B$7 -> 0 | L15: =I15*'01 Offer Pricing'!$B$8 -> 0 | M15: =SUM(J15:L15) -> 0 | N15: =H15*'01 Offer Pricing'!$B$9 -> 0 | O15: =I15*'01 Offer Pricing'!$B$10 -> 0 | P15: =C15*'01 Offer Pricing'!$B$11+D15*'01 Offer Pricing'!$B$12 -> 0 | Q15: =M15-N15-O15-P15 -> 0 | R15: 0 | S15: 0.9 | T15: 0
A16: 46171 | B16: Thứ 6 | C16: 0 | D16: 0 | E16: 0 | F16: 0 | G16: 0 | H16: =SUM(E16:G16) -> 0 | I16: 0 | J16: =C16*'01 Offer Pricing'!$B$5+D16*'01 Offer Pricing'!$B$6 -> 0 | K16: =H16*'01 Offer Pricing'!$B$7 -> 0 | L16: =I16*'01 Offer Pricing'!$B$8 -> 0 | M16: =SUM(J16:L16) -> 0 | N16: =H16*'01 Offer Pricing'!$B$9 -> 0 | O16: =I16*'01 Offer Pricing'!$B$10 -> 0 | P16: =C16*'01 Offer Pricing'!$B$11+D16*'01 Offer Pricing'!$B$12 -> 0 | Q16: =M16-N16-O16-P16 -> 0 | R16: 0 | S16: 0.9 | T16: 0
A17: 46172 | B17: Thứ 7 | C17: 0 | D17: 0 | E17: 0 | F17: 0 | G17: 0 | H17: =SUM(E17:G17) -> 0 | I17: 0 | J17: =C17*'01 Offer Pricing'!$B$5+D17*'01 Offer Pricing'!$B$6 -> 0 | K17: =H17*'01 Offer Pricing'!$B$7 -> 0 | L17: =I17*'01 Offer Pricing'!$B$8 -> 0 | M17: =SUM(J17:L17) -> 0 | N17: =H17*'01 Offer Pricing'!$B$9 -> 0 | O17: =I17*'01 Offer Pricing'!$B$10 -> 0 | P17: =C17*'01 Offer Pricing'!$B$11+D17*'01 Offer Pricing'!$B$12 -> 0 | Q17: =M17-N17-O17-P17 -> 0 | R17: 0 | S17: 0.9 | T17: 0
A18: 46173 | B18: CN | C18: 0 | D18: 0 | E18: 0 | F18: 0 | G18: 0 | H18: =SUM(E18:G18) -> 0 | I18: 0 | J18: =C18*'01 Offer Pricing'!$B$5+D18*'01 Offer Pricing'!$B$6 -> 0 | K18: =H18*'01 Offer Pricing'!$B$7 -> 0 | L18: =I18*'01 Offer Pricing'!$B$8 -> 0 | M18: =SUM(J18:L18) -> 0 | N18: =H18*'01 Offer Pricing'!$B$9 -> 0 | O18: =I18*'01 Offer Pricing'!$B$10 -> 0 | P18: =C18*'01 Offer Pricing'!$B$11+D18*'01 Offer Pricing'!$B$12 -> 0 | Q18: =M18-N18-O18-P18 -> 0 | R18: 0 | S18: 0.9 | T18: 0
... A34: 46189 | B34: Thứ 3 | C34: 0 | D34: 0 | E34: 0 | F34: 0 | G34: 0 | H34: =SUM(E34:G34) -> 0 | I34: 0 | J34: =C34*'01 Offer Pricing'!$B$5+D34*'01 Offer Pricing'!$B$6 -> 0 | K34: =H34*'01 Offer Pricing'!$B$7 -> 0 | L34: =I34*'01 Offer Pricing'!$B$8 -> 0 | M34: =SUM(J34:L34) -> 0 | N34: =H34*'01 Offer Pricing'!$B$9 -> 0 | O34: =I34*'01 Offer Pricing'!$B$10 -> 0 | P34: =C34*'01 Offer Pricing'!$B$11+D34*'01 Offer Pricing'!$B$12 -> 0 | Q34: =M34-N34-O34-P34 -> 0 | R34: 0 | S34: 0.9 | T34: 0

Sheet 06 KPI Dashboard
A1: KPI DASHBOARD – MEMBERSHIP PILOT 30 NGÀY
A2: Dashboard tự tính từ Ops Tracker và Offer Pricing để team theo dõi mỗi ngày
A4: Tổng DT | B4: LN gộp ước tính | C4: Thẻ Giọt Lành | D4: Thẻ Ban Mai | E4: Tổng chai sữa | F4: Set Ban Mai | G4: Đúng giờ TB | H4: Khiếu nại
A5: =SUM('05 Ops Tracker'!M5:M34) -> 0 | B5: =SUM('05 Ops Tracker'!Q5:Q34) -> 0 | C5: =SUM('05 Ops Tracker'!C5:C34) -> 0 | D5: =SUM('05 Ops Tracker'!D5:D34) -> 0 | E5: =SUM('05 Ops Tracker'!H5:H34) -> 0 | F5: =SUM('05 Ops Tracker'!I5:I34) -> 0 | G5: =AVERAGE('05 Ops Tracker'!S5:S34) -> 0.9 | H5: =SUM('05 Ops Tracker'!T5:T34) -> 0
A9: KPI | B9: Target | C9: Actual | D9: % đạt | E9: Trạng thái | F9: Ghi chú
A10: Thẻ Giọt Lành An Nhiên | B10: ='01 Offer Pricing'!$B$14 -> 300 | C10: =$C$5 -> 0 | D10: =IFERROR(C10/B10,0) -> 0 | E10: =IF(D10>=1,"Đạt",IF(D10>=0.7,"Đang tiến triển","Cần đẩy")) -> Cần đẩy | F10: Mục tiêu pilot
A11: Thẻ Ban Mai | B11: ='01 Offer Pricing'!$B$15 -> 50 | C11: =$D$5 -> 0 | D11: =IFERROR(C11/B11,0) -> 0 | E11: =IF(D11>=1,"Đạt",IF(D11>=0.7,"Đang tiến triển","Cần đẩy")) -> Cần đẩy | F11: Mục tiêu pilot
A12: Tổng doanh thu pilot | B12: ='01 Offer Pricing'!$B$18 -> 175650000 | C12: =$A$5 -> 0 | D12: =IFERROR(C12/B12,0) -> 0 | E12: =IF(D12>=1,"Đạt",IF(D12>=0.7,"Đang tiến triển","Cần đẩy")) -> Cần đẩy | F12: Tính cả thẻ + sữa + Ban Mai
A13: Tổng chai sữa | B13: ='01 Offer Pricing'!$B$16 -> 4500 | C13: =$E$5 -> 0 | D13: =IFERROR(C13/B13,0) -> 0 | E13: =IF(D13>=1,"Đạt",IF(D13>=0.7,"Đang tiến triển","Cần đẩy")) -> Cần đẩy | F13: Đo adoption và thói quen
A14: Set Ban Mai | B14: ='01 Offer Pricing'!$B$17 -> 600 | C14: =$F$5 -> 0 | D14: =IFERROR(C14/B14,0) -> 0 | E14: =IF(D14>=1,"Đạt",IF(D14>=0.7,"Đang tiến triển","Cần đẩy")) -> Cần đẩy | F14: Đo upsell/AOV
A15: Giao đúng giờ TB | B15: ='01 Offer Pricing'!$B$19 -> 0.9 | C15: =$G$5 -> 0.9 | D15: =IFERROR(C15/B15,0) -> 1 | E15: =IF(D15>=1,"Đạt",IF(D15>=0.7,"Đang tiến triển","Cần đẩy")) -> Đạt | F15: Vận hành sáng
A16: Hàng dư/hủy | B16: =ROUND(('01 Offer Pricing'!$B$16+'01 Offer Pricing'!$B$17)*0.07,0) -> 357 | C16: =SUM('05 Ops Tracker'!R5:R34) -> 0 | D16: =IFERROR(1-C16/B16,0) -> 1 | E16: =IF(C16<=B16,"Ổn","Cần xử lý") -> Ổn | F16: Ngưỡng gợi ý: <7% tổng sản lượng; chỉnh theo thực tế
A17: Khiếu nại | B17: =ROUND(('01 Offer Pricing'!$B$16+'01 Offer Pricing'!$B$17)*0.03,0) -> 153 | C17: =$H$5 -> 0 | D17: =IFERROR(1-C17/B17,0) -> 1 | E17: =IF(C17<=B17,"Ổn","Cần xử lý") -> Ổn | F17: Ngưỡng gợi ý: <3% tổng sản lượng; chỉnh theo thực tế
A21: Ngày | B21: Tổng DT | C21: LN gộp ước tính
A22: D01 | B22: ='05 Ops Tracker'!M5 -> 0 | C22: ='05 Ops Tracker'!Q5 -> 0
A23: D02 | B23: ='05 Ops Tracker'!M6 -> 0 | C23: ='05 Ops Tracker'!Q6 -> 0
A24: D03 | B24: ='05 Ops Tracker'!M7 -> 0 | C24: ='05 Ops Tracker'!Q7 -> 0
A25: D04 | B25: ='05 Ops Tracker'!M8 -> 0 | C25: ='05 Ops Tracker'!Q8 -> 0
A26: D05 | B26: ='05 Ops Tracker'!M9 -> 0 | C26: ='05 Ops Tracker'!Q9 -> 0
A27: D06 | B27: ='05 Ops Tracker'!M10 -> 0 | C27: ='05 Ops Tracker'!Q10 -> 0
A28: D07 | B28: ='05 Ops Tracker'!M11 -> 0 | C28: ='05 Ops Tracker'!Q11 -> 0
A29: D08 | B29: ='05 Ops Tracker'!M12 -> 0 | C29: ='05 Ops Tracker'!Q12 -> 0
A30: D09 | B30: ='05 Ops Tracker'!M13 -> 0 | C30: ='05 Ops Tracker'!Q13 -> 0
A31: D10 | B31: ='05 Ops Tracker'!M14 -> 0 | C31: ='05 Ops Tracker'!Q14 -> 0
A32: D11 | B32: ='05 Ops Tracker'!M15 -> 0 | C32: ='05 Ops Tracker'!Q15 -> 0
A33: D12 | B33: ='05 Ops Tracker'!M16 -> 0 | C33: ='05 Ops Tracker'!Q16 -> 0
... A51: D30 | B51: ='05 Ops Tracker'!M34 -> 0 | C51: ='05 Ops Tracker'!Q34 -> 0

Sheet 07 CRM Flow
A1: CRM & CUSTOMER JOURNEY CANVAS
A2: Kịch bản chăm sóc hội viên từ mua thẻ đến active, upsell và referral
A4: Giai đoạn | B4: Khách nghĩ gì? | C4: Brand cần làm | D4: Công cụ | E4: Trigger | F4: Owner | G4: Trạng thái | H4: Thông điệp mẫu | I4: Ghi chú
A5: Mua thẻ | B5: Mua xong dùng thế nào? | C5: Gửi welcome + hướng dẫn dùng thẻ | D5: Zalo/SMS/QR | E5: Ngay sau thanh toán | F5: CRM | G5: Chưa bắt đầu | H5: Chào mừng bạn đến với Giọt Lành An Nhiên... | I5: Gắn SĐT/QR
A6: Chưa dùng sau 24h | B6: Mai có vị gì? | C6: Nhắc menu ngày mai | D6: Zalo/Story | E6: 24h chưa giao dịch | F6: CRM | G6: Chưa bắt đầu | H6: Ngày mai có Mộc Mè, Lạc Hương, Mộc Đậu... | I6: Nhắc nhẹ, không spam
A7: Dùng lần đầu | B7: Vị có ngon không? | C7: Cảm ơn + hỏi feedback | D7: Zalo | E7: Sau giao dịch đầu tiên | F7: CSKH | G7: Chưa bắt đầu | H7: Bạn thấy vị hôm nay thế nào ạ? | I7: Lấy feedback thật
A8: Dùng 3 lần | B8: Có bữa sáng tiện không? | C8: Gợi ý Thẻ Ban Mai | D8: Zalo/Leader | E8: Sau 3 lần mua sữa | F8: Sales | G8: Chưa bắt đầu | H8: Bạn đã có thói quen sữa hạt rồi, thử Ban Mai nhé... | I8: Upsell đúng thời điểm
A9: Active 7 ngày | B9: Mình theo được rồi | C9: Mời challenge 21 ngày | D9: Zalo/Community | E9: Sau 7 ngày active | F9: CRM | G9: Chưa bắt đầu | H9: Cùng brand giữ 21 ngày Giọt Lành nhé... | I9: Tạo gắn bó
A10: Không dùng 14 ngày | B10: Bận/quên/thấy không cần | C10: Gửi menu mới hoặc voucher nhỏ | D10: Zalo | E10: 14 ngày không mua | F10: CRM | G10: Chưa bắt đầu | H10: Tụi mình có menu mới tuần này... | I10: Không giảm quá sâu
A11: Giới thiệu bạn | B11: Bạn mình cũng thích | C11: Kích hoạt referral | D11: Mã giới thiệu | E11: Sau 5+ lần mua | F11: Marketing | G11: Chưa bắt đầu | H11: Mời bạn mở thẻ, cả hai nhận ưu đãi... | I11: Tặng trải nghiệm nâng cấp

Sheet 08 Risk Rules
A1: RISK, RULES & BRAND GUARDRAILS
A2: Những rủi ro và nguyên tắc không được phá vỡ khi cả brand vận hành chiến dịch
A4: Rủi ro | B4: Mức độ | C4: Tác động | D4: Cách khóa | E4: Owner | F4: Deadline | G4: Trạng thái | H4: Chỉ báo sớm | I4: Phản ứng nhanh | J4: Ghi chú
A5: Khách hiểu nhầm 'trọn đời' | B5: Cao | C5: Kỳ vọng pháp lý/vận hành vượt khả năng | D5: Dùng 'đặc quyền dài hạn' và điều khoản điều chỉnh | E5: Brand/CSKH | G5: Chưa bắt đầu | H5: Khách hỏi thời hạn liên tục | I5: Gửi FAQ thống nhất
A6: Brand bị nhìn là rẻ | B6: Cao | C6: Mất định vị premium/wellness | D6: Không nói rẻ nhất; dùng ngôn ngữ đặc quyền | E6: Marketing | G6: Chưa bắt đầu | H6: Comment so sánh giá rẻ | I6: Đổi thông điệp/caption
A7: Cost Ban Mai bị vỡ | B7: Cao | C7: Lỗ hoặc biên quá mỏng | D7: Set chính 1 chai trà; mua thêm bằng ưu đãi riêng | E7: Ops/Finance | G7: Chưa bắt đầu | H7: Cost/set >40K | I7: Cắt bớt biến động topping
A8: Leader nói quá công dụng | B8: Cao | C8: Rủi ro niềm tin và claim sai | D8: Script chuẩn; cấm claim giảm cân/chữa bệnh/thải độc thần kỳ | E8: Sales Lead | G8: Chưa bắt đầu | H8: Caption claim quá đà | I8: Nhắc/khóa mã leader nếu tái phạm
A9: Khách dùng chung thẻ | B9: Trung bình | C9: Thất thoát doanh thu | D9: Gắn SĐT/QR; giới hạn 3 chai/ngày | E9: Ops/CRM | G9: Chưa bắt đầu | H9: Một SĐT mua bất thường | I9: Check lại quy trình
A10: Hàng dư/hủy cao | B10: Cao | C10: Đội cost và lãng phí | D10: Forecast theo active rate; Ban Mai pre-order | E10: Ops | G10: Chưa bắt đầu | H10: Hủy/dư >10% | I10: Giảm sản xuất ngày sau
A11: Dị ứng lạc/mè/đậu nành | B11: Cao | C11: Rủi ro an toàn và niềm tin | D11: Ghi rõ thành phần chính trên tem/menu/FAQ | E11: Ops/Brand | G11: Chưa bắt đầu | H11: Khách hỏi thành phần | I11: Cập nhật nhãn ngay
A12: Giao hàng sáng trễ | B12: Cao | C12: Mất niềm tin, giảm repeat | D12: Chỉ nhận vùng/điểm gom đủ năng lực; đo đúng giờ | E12: Ops | G12: Chưa bắt đầu | H12: Đúng giờ <90% | I12: Giảm tuyến/điểm giao
A13: Khách mua thẻ nhưng không dùng | B13: Trung bình | C13: Membership chết, khó upsell | D13: Welcome flow, nhắc menu, challenge 7 ngày | E13: CRM | G13: Chưa bắt đầu | H13: Active 7D <60% | I13: Gửi kích hoạt lại
A18: BRAND GUARDRAILS – Không được phá vỡ
A19: 1. Không gọi chương trình là 'rẻ nhất' hoặc 'sale xả'.
A20: 2. Không claim chữa bệnh, giảm cân, detox thần kỳ.
A21: 3. Không giấu thành phần mè, lạc, đậu nành trên tem/FAQ.
A22: 4. Không để set Ban Mai tiêu chuẩn có 1–3 chai trà; mặc định 1 chai trà.
A23: 5. Không mở rộng điểm giao nếu tỷ lệ đúng giờ dưới 90%.
A24: 6. Không trả hoa hồng nhiều tầng; chỉ trả theo doanh số thật.

Sheet Lists
A1: LISTS & VALIDATION
A2: Danh mục dùng cho dropdown trong các sheet tracker
A4: Status chung | B4: Leader Group | C4: Marketing Status | D4: Risk Level | E4: Owner | F4: Milk Flavor
A5: Chưa bắt đầu | B5: Yoga/Pilates/Gym | C5: Chưa bắt đầu | D5: Cao | E5: Marketing | F5: Mộc Mè
A6: Đang làm | B6: Văn phòng/HR | C6: Đang làm | D6: Trung bình | E6: Sales | F6: Lạc Hương
A7: Xong | B7: Spa/Salon | C7: Đã lên lịch | D7: Thấp | E7: Ops | F7: Mộc Đậu
A8: Blocked | B8: KOC | C8: Đã đăng | E8: CRM
A9: Đã cài | B9: Beauty/Fashion Shop | C9: Blocked | E9: Finance
A10: Tạm dừng | B10: Mẹ/Bếp sạch | E10: Brand
A11: Theo dõi | B11: Khác | E11: CSKH

Sheet 09 Strategy Core
A1: CORE STRATEGY CANVAS – Gieo Giọt Lành / Leader – Affiliate – Đại lý
A2: Bản core dùng để cả brand theo dõi: chiến lược cảm xúc, đối tượng, offer, flow tặng quà trước, chính sách level và KPI scale đội nhóm.
A4: 1. NORTH STAR
A5: Tên chương trình | B5: Gieo Giọt Lành | C5: Tư duy | D5: Tặng quà trước – hỏi trải nghiệm – mời lan tỏa – cấp mã – hỗ trợ 3 đơn đầu
A6: Sản phẩm mồi | B6: Thẻ Giọt Lành An Nhiên | C6: Giá trị | D6: 199K mở thẻ, sữa hạt 15K/chai, tối đa 3 chai/ngày
A7: Sản phẩm upsell | B7: Thẻ Ban Mai | C7: Giá trị | D7: 249K mở thẻ, set Ban Mai 60K
A8: Set quà lõi | B8: Mộc Mè – Lạc Hương – Mộc Đậu | C8: Cảm xúc cần tạo | D8: An toàn – uy tín – có lợi – dễ lan tỏa
A10: 2. EMOTIONAL JOURNEY CANVAS
A11: Tầng cảm xúc | B11: Rào cản cảm xúc | C11: Hành động của brand | D11: Nội dung truyền thông | E11: Chính sách/Quyền lợi | F11: KPI chuyển tầng | G11: Người phụ trách | H11: Ghi chú
A12: Được tặng | B12: Xa lạ, chưa an toàn | C12: Tặng đúng set, đúng tệp, đúng ngữ cảnh | D12: Card/ảnh/video: brand là ai, set quà là gì | E12: Không ép mua, quà trải nghiệm | F12: Tỷ lệ nhận quà | G12: Sales/Leader | H12: Gift-led activation
A13: Trải nghiệm | B13: Sợ sản phẩm không ngon/không uy tín | C13: Follow-up sau 24–48h, hỏi vị hợp gu | D13: Video BTS, feedback 3 vị | E13: Form feedback, voucher nhỏ | F13: Tỷ lệ phản hồi | G13: CRM | H13: Không hỏi quá chung chung
A14: Được mời lan tỏa | B14: Sợ bị biến thành người bán | C14: Hỏi: chị nghĩ sao nếu lan tỏa set này tới người chị thương? | D14: Câu chuyện món quà sáng lành | E14: Mã quà lan tỏa, quyền lợi mềm | F14: Tỷ lệ nhận mã | G14: Sales/Leader Manager | H14: Dùng từ lan tỏa thay cho bán hàng
A15: Có mã riêng | B15: Sợ không có lợi ích/không minh bạch | C15: Cấp mã, tracking, policy ngắn | D15: Ảnh 1 trang chính sách | E15: HH theo thẻ/set, payout tuần | F15: Số mã active | G15: CRM/Finance | H15: Không cần ôm hàng
A16: Có đơn đầu tiên | B16: Sợ bán khó | C16: Hỗ trợ 3 đơn đầu bằng script + sample | D16: Story template, inbox script, FAQ | E16: Bonus 3 đơn đầu | F16: Tỷ lệ có đơn đầu | G16: Leader Manager | H16: Mục tiêu nhỏ trước
A17: Leader active | B17: Sợ không duy trì được | C17: Training, dashboard, vinh danh | D17: Leaderboard, case study | E17: Level, bonus mốc, quyền lợi | F17: Active rate 30 ngày | G17: Sales Lead | H17: Scale bằng pod/captain
A20: 3. SCALE MODEL
A21: Tệp | B21: Cách tiếp cận | C21: Set quà phù hợp | D21: Level đầu vào | E21: KPI mở đầu | F21: Cách scale | G21: Rủi ro cần kiểm soát
A22: Người nhận quà | B22: Tặng quà / mối quan hệ | C22: Bộ Giọt Lành An Nhiên | D22: Người Gieo Giọt Lành | E22: 3 lời giới thiệu | F22: Cấp 5 mã quà lan tỏa | G22: Không ép thành CTV quá sớm
A23: Affiliate/CTV | B23: Dùng thử + chính sách ngắn | C23: Bộ Giọt Lành/Set Ban Mai | D23: Affiliate cơ bản | E23: 3 đơn đầu | F23: Content kit + script + payout tuần | G23: Không để họ tự nghĩ content
A24: Leader | B24: Tasting + training | C24: Set Ban Mai | D24: Đại sứ/Leader An Nhiên | E24: 10–20 thẻ/tháng | F24: Pod 5–10 leader | G24: Overpromise công dụng/giá
A25: Đại lý/Điểm gom | B25: Sự kiện/office tasting | C25: Set Ban Mai | D25: Đối tác thử nghiệm/Điểm gom | E25: 50–100 set/tháng | F25: Điểm gom theo khu vực | G25: Vỡ cost/giao trễ
A26: Captain | B26: Nâng cấp từ leader mạnh | C26: Tùy tệp | D26: Captain Giọt Lành | E26: Quản 5–10 leader | F26: Mở pod mới | G26: Thưởng tuyển người không có đơn thật
A29: 4. 30-60-90 DAY ROADMAP
A30: Giai đoạn | B30: Mục tiêu | C30: Việc cần làm | D30: KPI chính | E30: Điều kiện để scale
A31: 0–30 ngày | B31: Chứng minh mô hình gift-led hoạt động | C31: Tặng 100 set chọn lọc, tổ chức 1–2 tasting, cấp mã cho nhóm phản hồi tích cực | D31: 5–10 leader có đơn đầu | E31: Tỷ lệ phản hồi ≥50%, lỗi vận hành thấp
A32: 31–60 ngày | B32: Scale leader/đối tác active | C32: Mở 3–5 điểm gom, training hằng tuần, leaderboard, payout đều | D32: 20–30 leader active, 300–500 thẻ | E32: Active rate khách ≥35%, giao đúng giờ >90%
A33: 61–90 ngày | B33: Nhân bản theo pod/captain | C33: Nâng leader mạnh lên Captain, mở pod theo khu vực/cộng đồng | D33: 5 Captain, 50 leader, 1.000+ hội viên | E33: Hệ thống CRM/payout đủ chắc

Sheet 10 Partners
A1: DANH SÁCH ĐỐI TÁC LIÊN KẾT – Partner / Đại lý / Điểm gom
A2: Nhập thông tin đối tác từ cột A:R và U:Z/AG:AI. Các cột S:T, AA:AF tự tính điểm, level, doanh thu, hoa hồng, thưởng và tiến độ.
A3: Partner ID | B3: Ngày liên hệ | C3: Tên đối tác | D3: Loại đối tác | E3: Người liên hệ | F3: SĐT/Zalo | G3: Khu vực | H3: Nguồn liên hệ | I3: Tệp khách chính | J3: Hình thức tiếp cận | K3: Set quà/Sự kiện | L3: Ngày gửi quà/sự kiện | M3: Feedback/cảm nhận | N3: Trạng thái cảm xúc | O3: Level hiện tại | P3: Điểm tiềm năng | Q3: Điểm fit/uy tín | R3: Điểm bán/group order | S3: Tổng điểm | T3: Level gợi ý | U3: Target thẻ GL | V3: Target thẻ BM | W3: Target set BM | X3: Thẻ GL bán | Y3: Thẻ BM bán | Z3: Set BM bán | AA3: Doanh thu ghi nhận | AB3: Hoa hồng tạm tính | AC3: Bonus tạm tính | AD3: Tổng payout | AE3: Tiến độ thẻ | AF3: Tiến độ set | AG3: Follow-up kế tiếp | AH3: Owner | AI3: Ghi chú
A4: P001 | B4: 46160 | C4: Lotus Yoga Studio | D4: Yoga/Pilates/Gym | E4: Chị An | F4: 090xxx001 | G4: Q.1 | H4: Mối quan hệ | I4: Wellness/Yoga | J4: Sự kiện | K4: Set Ban Mai | L4: 46162 | M4: Ấn tượng với Set Ban Mai | N4: Đã thử | O4: Đối tác thử nghiệm | P4: 5 | Q4: 5 | R4: 4 | S4: =IF(C4="","",SUM(P4:R4)) -> 14 | T4: =IF(C4="","",IF(S4>=13,"Đối tác chiến lược",IF(S4>=10,"Đại lý",IF(S4>=7,"Điểm gom",IF(S4>=1,"Theo dõi",""))))) -> Đối tác chiến lược | U4: 20 | V4: 5 | W4: 80 | X4: 12 | Y4: 3 | Z4: 35 | AA4: =IF(C4="","",X4*199000+Y4*249000+Z4*60000) -> 5235000 | AB4: =IF(C4="","",IFERROR(X4*VLOOKUP(IF(O4="",T4,O4),'13 Policy Matrix'!$A$4:$F$30,4,FALSE)+Y4*VLOOKUP(IF(O4="",T4,O4),'13 Policy Matrix'!$A$4:$F$30,5,FALSE)+Z4*VLOOKUP(IF(O4="",T4,O4),'13 Policy Matrix'!$A$4:$F$30,6,FALSE),0)) -> 0 | AC4: =IF(C4="","",IF(X4+Y4>=50,1000000,IF(X4+Y4>=20,300000,IF(X4+Y4>=10,100000,0)))+IF(Z4>=100,300000,0)) -> 100000 | AD4: =IF(C4="","",AB4+AC4) -> 100000 | AE4: =IFERROR((X4+Y4)/(U4+V4),0) -> 0.6 | AF4: =IFERROR(Z4/W4,0) -> 0.4375 | AG4: 46164 | AH4: Sales | AI4: Hẹn tasting tại studio
A5: P002 | B5: 46161 | C5: HR ABC Office | D5: Văn phòng/HR | E5: Anh Minh | F5: 090xxx002 | G5: Q.3 | H5: Referral từ nội bộ | I5: Văn phòng/HR | J5: Tặng quà trực tiếp | K5: Bộ Giọt Lành An Nhiên | L5: 46163 | M5: Đội nhóm muốn thử bữa sáng | N5: Quan tâm | O5: Điểm gom | P5: 4 | Q5: 4 | R5: 5 | S5: =IF(C5="","",SUM(P5:R5)) -> 13 | T5: =IF(C5="","",IF(S5>=13,"Đối tác chiến lược",IF(S5>=10,"Đại lý",IF(S5>=7,"Điểm gom",IF(S5>=1,"Theo dõi",""))))) -> Đối tác chiến lược | U5: 30 | V5: 10 | W5: 100 | X5: 18 | Y5: 4 | Z5: 42 | AA5: =IF(C5="","",X5*199000+Y5*249000+Z5*60000) -> 7098000 | AB5: =IF(C5="","",IFERROR(X5*VLOOKUP(IF(O5="",T5,O5),'13 Policy Matrix'!$A$4:$F$30,4,FALSE)+Y5*VLOOKUP(IF(O5="",T5,O5),'13 Policy Matrix'!$A$4:$F$30,5,FALSE)+Z5*VLOOKUP(IF(O5="",T5,O5),'13 Policy Matrix'!$A$4:$F$30,6,FALSE),0)) -> 0 | AC5: =IF(C5="","",IF(X5+Y5>=50,1000000,IF(X5+Y5>=20,300000,IF(X5+Y5>=10,100000,0)))+IF(Z5>=100,300000,0)) -> 300000 | AD5: =IF(C5="","",AB5+AC5) -> 300000 | AE5: =IFERROR((X5+Y5)/(U5+V5),0) -> 0.55 | AF5: =IFERROR(Z5/W5,0) -> 0.42 | AG5: 46165 | AH5: Leader Manager | AI5: Có thể mở điểm gom sáng
A6: P003 | B6: 46162 | C6: Bloom Spa | D6: Spa/Salon | E6: Chị Ly | F6: 090xxx003 | G6: Q.7 | H6: Cold outreach | I6: Spa/Beauty | J6: Gửi quà | K6: Sample 3 vị | L6: 46164 | M6: Chưa phản hồi | N6: Đã nhận quà | O6: Theo dõi | P6: 3 | Q6: 4 | R6: 2 | S6: =IF(C6="","",SUM(P6:R6)) -> 9 | T6: =IF(C6="","",IF(S6>=13,"Đối tác chiến lược",IF(S6>=10,"Đại lý",IF(S6>=7,"Điểm gom",IF(S6>=1,"Theo dõi",""))))) -> Điểm gom | U6: 10 | V6: 3 | W6: 20 | X6: 2 | Y6: 0 | Z6: 0 | AA6: =IF(C6="","",X6*199000+Y6*249000+Z6*60000) -> 398000 | AB6: =IF(C6="","",IFERROR(X6*VLOOKUP(IF(O6="",T6,O6),'13 Policy Matrix'!$A$4:$F$30,4,FALSE)+Y6*VLOOKUP(IF(O6="",T6,O6),'13 Policy Matrix'!$A$4:$F$30,5,FALSE)+Z6*VLOOKUP(IF(O6="",T6,O6),'13 Policy Matrix'!$A$4:$F$30,6,FALSE),0)) -> 0 | AC6: =IF(C6="","",IF(X6+Y6>=50,1000000,IF(X6+Y6>=20,300000,IF(X6+Y6>=10,100000,0)))+IF(Z6>=100,300000,0)) -> 0 | AD6: =IF(C6="","",AB6+AC6) -> 0 | AE6: =IFERROR((X6+Y6)/(U6+V6),0) -> 0.15384615 | AF6: =IFERROR(Z6/W6,0) -> 0 | AG6: 46167 | AH6: Marketing | AI6: Follow-up sau 48h
S7: =IF(C7="","",SUM(P7:R7)) | T7: =IF(C7="","",IF(S7>=13,"Đối tác chiến lược",IF(S7>=10,"Đại lý",IF(S7>=7,"Điểm gom",IF(S7>=1,"Theo dõi",""))))) | AA7: =IF(C7="","",X7*199000+Y7*249000+Z7*60000) | AB7: =IF(C7="","",IFERROR(X7*VLOOKUP(IF(O7="",T7,O7),'13 Policy Matrix'!$A$4:$F$30,4,FALSE)+Y7*VLOOKUP(IF(O7="",T7,O7),'13 Policy Matrix'!$A$4:$F$30,5,FALSE)+Z7*VLOOKUP(IF(O7="",T7,O7),'13 Policy Matrix'!$A$4:$F$30,6,FALSE),0)) | AC7: =IF(C7="","",IF(X7+Y7>=50,1000000,IF(X7+Y7>=20,300000,IF(X7+Y7>=10,100000,0)))+IF(Z7>=100,300000,0)) | AD7: =IF(C7="","",AB7+AC7) | AE7: =IFERROR((X7+Y7)/(U7+V7),0) -> 0 | AF7: =IFERROR(Z7/W7,0) -> 0
S8: =IF(C8="","",SUM(P8:R8)) | T8: =IF(C8="","",IF(S8>=13,"Đối tác chiến lược",IF(S8>=10,"Đại lý",IF(S8>=7,"Điểm gom",IF(S8>=1,"Theo dõi",""))))) | AA8: =IF(C8="","",X8*199000+Y8*249000+Z8*60000) | AB8: =IF(C8="","",IFERROR(X8*VLOOKUP(IF(O8="",T8,O8),'13 Policy Matrix'!$A$4:$F$30,4,FALSE)+Y8*VLOOKUP(IF(O8="",T8,O8),'13 Policy Matrix'!$A$4:$F$30,5,FALSE)+Z8*VLOOKUP(IF(O8="",T8,O8),'13 Policy Matrix'!$A$4:$F$30,6,FALSE),0)) | AC8: =IF(C8="","",IF(X8+Y8>=50,1000000,IF(X8+Y8>=20,300000,IF(X8+Y8>=10,100000,0)))+IF(Z8>=100,300000,0)) | AD8: =IF(C8="","",AB8+AC8) | AE8: =IFERROR((X8+Y8)/(U8+V8),0) -> 0 | AF8: =IFERROR(Z8/W8,0) -> 0
S9: =IF(C9="","",SUM(P9:R9)) | T9: =IF(C9="","",IF(S9>=13,"Đối tác chiến lược",IF(S9>=10,"Đại lý",IF(S9>=7,"Điểm gom",IF(S9>=1,"Theo dõi",""))))) | AA9: =IF(C9="","",X9*199000+Y9*249000+Z9*60000) | AB9: =IF(C9="","",IFERROR(X9*VLOOKUP(IF(O9="",T9,O9),'13 Policy Matrix'!$A$4:$F$30,4,FALSE)+Y9*VLOOKUP(IF(O9="",T9,O9),'13 Policy Matrix'!$A$4:$F$30,5,FALSE)+Z9*VLOOKUP(IF(O9="",T9,O9),'13 Policy Matrix'!$A$4:$F$30,6,FALSE),0)) | AC9: =IF(C9="","",IF(X9+Y9>=50,1000000,IF(X9+Y9>=20,300000,IF(X9+Y9>=10,100000,0)))+IF(Z9>=100,300000,0)) | AD9: =IF(C9="","",AB9+AC9) | AE9: =IFERROR((X9+Y9)/(U9+V9),0) -> 0 | AF9: =IFERROR(Z9/W9,0) -> 0
S10: =IF(C10="","",SUM(P10:R10)) | T10: =IF(C10="","",IF(S10>=13,"Đối tác chiến lược",IF(S10>=10,"Đại lý",IF(S10>=7,"Điểm gom",IF(S10>=1,"Theo dõi",""))))) | AA10: =IF(C10="","",X10*199000+Y10*249000+Z10*60000) | AB10: =IF(C10="","",IFERROR(X10*VLOOKUP(IF(O10="",T10,O10),'13 Policy Matrix'!$A$4:$F$30,4,FALSE)+Y10*VLOOKUP(IF(O10="",T10,O10),'13 Policy Matrix'!$A$4:$F$30,5,FALSE)+Z10*VLOOKUP(IF(O10="",T10,O10),'13 Policy Matrix'!$A$4:$F$30,6,FALSE),0)) | AC10: =IF(C10="","",IF(X10+Y10>=50,1000000,IF(X10+Y10>=20,300000,IF(X10+Y10>=10,100000,0)))+IF(Z10>=100,300000,0)) | AD10: =IF(C10="","",AB10+AC10) | AE10: =IFERROR((X10+Y10)/(U10+V10),0) -> 0 | AF10: =IFERROR(Z10/W10,0) -> 0
S11: =IF(C11="","",SUM(P11:R11)) | T11: =IF(C11="","",IF(S11>=13,"Đối tác chiến lược",IF(S11>=10,"Đại lý",IF(S11>=7,"Điểm gom",IF(S11>=1,"Theo dõi",""))))) | AA11: =IF(C11="","",X11*199000+Y11*249000+Z11*60000) | AB11: =IF(C11="","",IFERROR(X11*VLOOKUP(IF(O11="",T11,O11),'13 Policy Matrix'!$A$4:$F$30,4,FALSE)+Y11*VLOOKUP(IF(O11="",T11,O11),'13 Policy Matrix'!$A$4:$F$30,5,FALSE)+Z11*VLOOKUP(IF(O11="",T11,O11),'13 Policy Matrix'!$A$4:$F$30,6,FALSE),0)) | AC11: =IF(C11="","",IF(X11+Y11>=50,1000000,IF(X11+Y11>=20,300000,IF(X11+Y11>=10,100000,0)))+IF(Z11>=100,300000,0)) | AD11: =IF(C11="","",AB11+AC11) | AE11: =IFERROR((X11+Y11)/(U11+V11),0) -> 0 | AF11: =IFERROR(Z11/W11,0) -> 0
S12: =IF(C12="","",SUM(P12:R12)) | T12: =IF(C12="","",IF(S12>=13,"Đối tác chiến lược",IF(S12>=10,"Đại lý",IF(S12>=7,"Điểm gom",IF(S12>=1,"Theo dõi",""))))) | AA12: =IF(C12="","",X12*199000+Y12*249000+Z12*60000) | AB12: =IF(C12="","",IFERROR(X12*VLOOKUP(IF(O12="",T12,O12),'13 Policy Matrix'!$A$4:$F$30,4,FALSE)+Y12*VLOOKUP(IF(O12="",T12,O12),'13 Policy Matrix'!$A$4:$F$30,5,FALSE)+Z12*VLOOKUP(IF(O12="",T12,O12),'13 Policy Matrix'!$A$4:$F$30,6,FALSE),0)) | AC12: =IF(C12="","",IF(X12+Y12>=50,1000000,IF(X12+Y12>=20,300000,IF(X12+Y12>=10,100000,0)))+IF(Z12>=100,300000,0)) | AD12: =IF(C12="","",AB12+AC12) | AE12: =IFERROR((X12+Y12)/(U12+V12),0) -> 0 | AF12: =IFERROR(Z12/W12,0) -> 0
S13: =IF(C13="","",SUM(P13:R13)) | T13: =IF(C13="","",IF(S13>=13,"Đối tác chiến lược",IF(S13>=10,"Đại lý",IF(S13>=7,"Điểm gom",IF(S13>=1,"Theo dõi",""))))) | AA13: =IF(C13="","",X13*199000+Y13*249000+Z13*60000) | AB13: =IF(C13="","",IFERROR(X13*VLOOKUP(IF(O13="",T13,O13),'13 Policy Matrix'!$A$4:$F$30,4,FALSE)+Y13*VLOOKUP(IF(O13="",T13,O13),'13 Policy Matrix'!$A$4:$F$30,5,FALSE)+Z13*VLOOKUP(IF(O13="",T13,O13),'13 Policy Matrix'!$A$4:$F$30,6,FALSE),0)) | AC13: =IF(C13="","",IF(X13+Y13>=50,1000000,IF(X13+Y13>=20,300000,IF(X13+Y13>=10,100000,0)))+IF(Z13>=100,300000,0)) | AD13: =IF(C13="","",AB13+AC13) | AE13: =IFERROR((X13+Y13)/(U13+V13),0) -> 0 | AF13: =IFERROR(Z13/W13,0) -> 0
S14: =IF(C14="","",SUM(P14:R14)) | T14: =IF(C14="","",IF(S14>=13,"Đối tác chiến lược",IF(S14>=10,"Đại lý",IF(S14>=7,"Điểm gom",IF(S14>=1,"Theo dõi",""))))) | AA14: =IF(C14="","",X14*199000+Y14*249000+Z14*60000) | AB14: =IF(C14="","",IFERROR(X14*VLOOKUP(IF(O14="",T14,O14),'13 Policy Matrix'!$A$4:$F$30,4,FALSE)+Y14*VLOOKUP(IF(O14="",T14,O14),'13 Policy Matrix'!$A$4:$F$30,5,FALSE)+Z14*VLOOKUP(IF(O14="",T14,O14),'13 Policy Matrix'!$A$4:$F$30,6,FALSE),0)) | AC14: =IF(C14="","",IF(X14+Y14>=50,1000000,IF(X14+Y14>=20,300000,IF(X14+Y14>=10,100000,0)))+IF(Z14>=100,300000,0)) | AD14: =IF(C14="","",AB14+AC14) | AE14: =IFERROR((X14+Y14)/(U14+V14),0) -> 0 | AF14: =IFERROR(Z14/W14,0) -> 0
S15: =IF(C15="","",SUM(P15:R15)) | T15: =IF(C15="","",IF(S15>=13,"Đối tác chiến lược",IF(S15>=10,"Đại lý",IF(S15>=7,"Điểm gom",IF(S15>=1,"Theo dõi",""))))) | AA15: =IF(C15="","",X15*199000+Y15*249000+Z15*60000) | AB15: =IF(C15="","",IFERROR(X15*VLOOKUP(IF(O15="",T15,O15),'13 Policy Matrix'!$A$4:$F$30,4,FALSE)+Y15*VLOOKUP(IF(O15="",T15,O15),'13 Policy Matrix'!$A$4:$F$30,5,FALSE)+Z15*VLOOKUP(IF(O15="",T15,O15),'13 Policy Matrix'!$A$4:$F$30,6,FALSE),0)) | AC15: =IF(C15="","",IF(X15+Y15>=50,1000000,IF(X15+Y15>=20,300000,IF(X15+Y15>=10,100000,0)))+IF(Z15>=100,300000,0)) | AD15: =IF(C15="","",AB15+AC15) | AE15: =IFERROR((X15+Y15)/(U15+V15),0) -> 0 | AF15: =IFERROR(Z15/W15,0) -> 0
S16: =IF(C16="","",SUM(P16:R16)) | T16: =IF(C16="","",IF(S16>=13,"Đối tác chiến lược",IF(S16>=10,"Đại lý",IF(S16>=7,"Điểm gom",IF(S16>=1,"Theo dõi",""))))) | AA16: =IF(C16="","",X16*199000+Y16*249000+Z16*60000) | AB16: =IF(C16="","",IFERROR(X16*VLOOKUP(IF(O16="",T16,O16),'13 Policy Matrix'!$A$4:$F$30,4,FALSE)+Y16*VLOOKUP(IF(O16="",T16,O16),'13 Policy Matrix'!$A$4:$F$30,5,FALSE)+Z16*VLOOKUP(IF(O16="",T16,O16),'13 Policy Matrix'!$A$4:$F$30,6,FALSE),0)) | AC16: =IF(C16="","",IF(X16+Y16>=50,1000000,IF(X16+Y16>=20,300000,IF(X16+Y16>=10,100000,0)))+IF(Z16>=100,300000,0)) | AD16: =IF(C16="","",AB16+AC16) | AE16: =IFERROR((X16+Y16)/(U16+V16),0) -> 0 | AF16: =IFERROR(Z16/W16,0) -> 0
S17: =IF(C17="","",SUM(P17:R17)) | T17: =IF(C17="","",IF(S17>=13,"Đối tác chiến lược",IF(S17>=10,"Đại lý",IF(S17>=7,"Điểm gom",IF(S17>=1,"Theo dõi",""))))) | AA17: =IF(C17="","",X17*199000+Y17*249000+Z17*60000) | AB17: =IF(C17="","",IFERROR(X17*VLOOKUP(IF(O17="",T17,O17),'13 Policy Matrix'!$A$4:$F$30,4,FALSE)+Y17*VLOOKUP(IF(O17="",T17,O17),'13 Policy Matrix'!$A$4:$F$30,5,FALSE)+Z17*VLOOKUP(IF(O17="",T17,O17),'13 Policy Matrix'!$A$4:$F$30,6,FALSE),0)) | AC17: =IF(C17="","",IF(X17+Y17>=50,1000000,IF(X17+Y17>=20,300000,IF(X17+Y17>=10,100000,0)))+IF(Z17>=100,300000,0)) | AD17: =IF(C17="","",AB17+AC17) | AE17: =IFERROR((X17+Y17)/(U17+V17),0) -> 0 | AF17: =IFERROR(Z17/W17,0) -> 0
S18: =IF(C18="","",SUM(P18:R18)) | T18: =IF(C18="","",IF(S18>=13,"Đối tác chiến lược",IF(S18>=10,"Đại lý",IF(S18>=7,"Điểm gom",IF(S18>=1,"Theo dõi",""))))) | AA18: =IF(C18="","",X18*199000+Y18*249000+Z18*60000) | AB18: =IF(C18="","",IFERROR(X18*VLOOKUP(IF(O18="",T18,O18),'13 Policy Matrix'!$A$4:$F$30,4,FALSE)+Y18*VLOOKUP(IF(O18="",T18,O18),'13 Policy Matrix'!$A$4:$F$30,5,FALSE)+Z18*VLOOKUP(IF(O18="",T18,O18),'13 Policy Matrix'!$A$4:$F$30,6,FALSE),0)) | AC18: =IF(C18="","",IF(X18+Y18>=50,1000000,IF(X18+Y18>=20,300000,IF(X18+Y18>=10,100000,0)))+IF(Z18>=100,300000,0)) | AD18: =IF(C18="","",AB18+AC18) | AE18: =IFERROR((X18+Y18)/(U18+V18),0) -> 0 | AF18: =IFERROR(Z18/W18,0) -> 0
... S303: =IF(C303="","",SUM(P303:R303)) | T303: =IF(C303="","",IF(S303>=13,"Đối tác chiến lược",IF(S303>=10,"Đại lý",IF(S303>=7,"Điểm gom",IF(S303>=1,"Theo dõi",""))))) | AA303: =IF(C303="","",X303*199000+Y303*249000+Z303*60000) | AB303: =IF(C303="","",IFERROR(X303*VLOOKUP(IF(O303="",T303,O303),'13 Policy Matrix'!$A$4:$F$30,4,FALSE)+Y303*VLOOKUP(IF(O303="",T303,O303),'13 Policy Matrix'!$A$4:$F$30,5,FALSE)+Z303*VLOOKUP(IF(O303="",T303,O303),'13 Policy Matrix'!$A$4:$F$30,6,FALSE),0)) | AC303: =IF(C303="","",IF(X303+Y303>=50,1000000,IF(X303+Y303>=20,300000,IF(X303+Y303>=10,100000,0)))+IF(Z303>=100,300000,0)) | AD303: =IF(C303="","",AB303+AC303) | AE303: =IFERROR((X303+Y303)/(U303+V303),0) -> 0 | AF303: =IFERROR(Z303/W303,0) -> 0

Sheet 11 CTV Product
A1: DANH SÁCH CTV PHÁT TRIỂN SẢN PHẨM / AFFILIATE / NGƯỜI GIỚI THIỆU
A2: Theo dõi CTV từ nhận quà → feedback → nhận mã → bán/gom đơn. Cột P:Q và X:AE tự tính level gợi ý, doanh thu, hoa hồng, bonus, tỷ lệ chuyển đổi và tiến độ KPI.
A3: CTV ID | B3: Ngày onboard | C3: Họ tên | D3: Nhóm CTV | E3: Kênh/Tệp | F3: SĐT/Zalo | G3: Khu vực | H3: Nguồn | I3: Set quà đã nhận | J3: Feedback chính | K3: Trạng thái cảm xúc | L3: Level hiện tại | M3: Điểm fit | N3: Điểm tương tác | O3: Điểm network | P3: Tổng điểm | Q3: Level gợi ý | R3: Người được tặng quà | S3: Số phản hồi | T3: Lead giới thiệu | U3: Thẻ GL bán | V3: Thẻ BM bán | W3: Set BM bán | X3: Doanh thu ghi nhận | Y3: Hoa hồng tạm tính | Z3: Bonus tạm tính | AA3: Tổng payout | AB3: Tỷ lệ phản hồi | AC3: Tỷ lệ lead→thẻ | AD3: KPI đơn/tháng | AE3: Tiến độ KPI | AF3: Payout status | AG3: Owner | AH3: Ghi chú
A4: C001 | B4: 46160 | C4: Nguyễn Hà | D4: Đại sứ Ban Mai | E4: Lifestyle local | F4: 091xxx001 | G4: Q.1 | H4: Mối quan hệ | I4: Bộ Giọt Lành An Nhiên | J4: Thích Lạc Hương | K4: Đã cấp mã | L4: Đại sứ Ban Mai | M4: 5 | N4: 5 | O4: 4 | P4: =IF(C4="","",SUM(M4:O4)) -> 14 | Q4: =IF(C4="","",IF((U4+V4)>=20,"Leader An Nhiên",IF((U4+V4)>=5,"Đại sứ Ban Mai",IF(P4>=10,"Affiliate cơ bản",IF(P4>=1,"Người Gieo Giọt Lành",""))))) -> Đại sứ Ban Mai | R4: 10 | S4: 8 | T4: 12 | U4: 6 | V4: 2 | W4: 8 | X4: =IF(C4="","",U4*199000+V4*249000+W4*60000) -> 2172000 | Y4: =IF(C4="","",IFERROR(U4*VLOOKUP(IF(L4="",Q4,L4),'13 Policy Matrix'!$A$4:$F$30,4,FALSE)+V4*VLOOKUP(IF(L4="",Q4,L4),'13 Policy Matrix'!$A$4:$F$30,5,FALSE)+W4*VLOOKUP(IF(L4="",Q4,L4),'13 Policy Matrix'!$A$4:$F$30,6,FALSE),0)) -> 0 | Z4: =IF(C4="","",IF(U4+V4>=50,1000000,IF(U4+V4>=20,300000,IF(U4+V4>=10,100000,0)))+IF(W4>=100,300000,0)) -> 0 | AA4: =IF(C4="","",Y4+Z4) -> 0 | AB4: =IFERROR(S4/R4,0) -> 0.8 | AC4: =IFERROR((U4+V4)/T4,0) -> 0.66666667 | AD4: 20 | AE4: =IFERROR((U4+V4+W4)/AD4,0) -> 0.8 | AF4: Chưa thanh toán | AG4: Leader Manager | AH4: Tệp nữ văn phòng tốt
A5: C002 | B5: 46161 | C5: Trần Mai | D5: Người giới thiệu | E5: Khách thân | F5: 091xxx002 | G5: Q.3 | H5: Khách cũ | I5: Set Ban Mai | J5: Thích concept quà sáng | K5: Quan tâm | L5: Người Gieo Giọt Lành | M5: 4 | N5: 4 | O5: 3 | P5: =IF(C5="","",SUM(M5:O5)) -> 11 | Q5: =IF(C5="","",IF((U5+V5)>=20,"Leader An Nhiên",IF((U5+V5)>=5,"Đại sứ Ban Mai",IF(P5>=10,"Affiliate cơ bản",IF(P5>=1,"Người Gieo Giọt Lành",""))))) -> Affiliate cơ bản | R5: 5 | S5: 4 | T5: 5 | U5: 2 | V5: 0 | W5: 1 | X5: =IF(C5="","",U5*199000+V5*249000+W5*60000) -> 458000 | Y5: =IF(C5="","",IFERROR(U5*VLOOKUP(IF(L5="",Q5,L5),'13 Policy Matrix'!$A$4:$F$30,4,FALSE)+V5*VLOOKUP(IF(L5="",Q5,L5),'13 Policy Matrix'!$A$4:$F$30,5,FALSE)+W5*VLOOKUP(IF(L5="",Q5,L5),'13 Policy Matrix'!$A$4:$F$30,6,FALSE),0)) -> 0 | Z5: =IF(C5="","",IF(U5+V5>=50,1000000,IF(U5+V5>=20,300000,IF(U5+V5>=10,100000,0)))+IF(W5>=100,300000,0)) -> 0 | AA5: =IF(C5="","",Y5+Z5) -> 0 | AB5: =IFERROR(S5/R5,0) -> 0.8 | AC5: =IFERROR((U5+V5)/T5,0) -> 0.4 | AD5: 8 | AE5: =IFERROR((U5+V5+W5)/AD5,0) -> 0.375 | AF5: Chưa thanh toán | AG5: CRM | AH5: Bắt đầu bằng 5 mã quà
A6: C003 | B6: 46162 | C6: Lê An | D6: CTV test sản phẩm | E6: Yoga | F6: 091xxx003 | G6: Q.7 | H6: Sự kiện | I6: Sample 3 vị | J6: Feedback về độ ngọt | K6: Đã thử | L6: Theo dõi | M6: 4 | N6: 3 | O6: 4 | P6: =IF(C6="","",SUM(M6:O6)) -> 11 | Q6: =IF(C6="","",IF((U6+V6)>=20,"Leader An Nhiên",IF((U6+V6)>=5,"Đại sứ Ban Mai",IF(P6>=10,"Affiliate cơ bản",IF(P6>=1,"Người Gieo Giọt Lành",""))))) -> Affiliate cơ bản | R6: 3 | S6: 2 | T6: 2 | U6: 0 | V6: 0 | W6: 0 | X6: =IF(C6="","",U6*199000+V6*249000+W6*60000) -> 0 | Y6: =IF(C6="","",IFERROR(U6*VLOOKUP(IF(L6="",Q6,L6),'13 Policy Matrix'!$A$4:$F$30,4,FALSE)+V6*VLOOKUP(IF(L6="",Q6,L6),'13 Policy Matrix'!$A$4:$F$30,5,FALSE)+W6*VLOOKUP(IF(L6="",Q6,L6),'13 Policy Matrix'!$A$4:$F$30,6,FALSE),0)) -> 0 | Z6: =IF(C6="","",IF(U6+V6>=50,1000000,IF(U6+V6>=20,300000,IF(U6+V6>=10,100000,0)))+IF(W6>=100,300000,0)) -> 0 | AA6: =IF(C6="","",Y6+Z6) -> 0 | AB6: =IFERROR(S6/R6,0) -> 0.66666667 | AC6: =IFERROR((U6+V6)/T6,0) -> 0 | AD6: 5 | AE6: =IFERROR((U6+V6+W6)/AD6,0) -> 0 | AF6: Không đủ điều kiện | AG6: Marketing | AH6: Chưa cấp mã bán
P7: =IF(C7="","",SUM(M7:O7)) | Q7: =IF(C7="","",IF((U7+V7)>=20,"Leader An Nhiên",IF((U7+V7)>=5,"Đại sứ Ban Mai",IF(P7>=10,"Affiliate cơ bản",IF(P7>=1,"Người Gieo Giọt Lành",""))))) | X7: =IF(C7="","",U7*199000+V7*249000+W7*60000) | Y7: =IF(C7="","",IFERROR(U7*VLOOKUP(IF(L7="",Q7,L7),'13 Policy Matrix'!$A$4:$F$30,4,FALSE)+V7*VLOOKUP(IF(L7="",Q7,L7),'13 Policy Matrix'!$A$4:$F$30,5,FALSE)+W7*VLOOKUP(IF(L7="",Q7,L7),'13 Policy Matrix'!$A$4:$F$30,6,FALSE),0)) | Z7: =IF(C7="","",IF(U7+V7>=50,1000000,IF(U7+V7>=20,300000,IF(U7+V7>=10,100000,0)))+IF(W7>=100,300000,0)) | AA7: =IF(C7="","",Y7+Z7) | AB7: =IFERROR(S7/R7,0) -> 0 | AC7: =IFERROR((U7+V7)/T7,0) -> 0 | AE7: =IFERROR((U7+V7+W7)/AD7,0) -> 0
P8: =IF(C8="","",SUM(M8:O8)) | Q8: =IF(C8="","",IF((U8+V8)>=20,"Leader An Nhiên",IF((U8+V8)>=5,"Đại sứ Ban Mai",IF(P8>=10,"Affiliate cơ bản",IF(P8>=1,"Người Gieo Giọt Lành",""))))) | X8: =IF(C8="","",U8*199000+V8*249000+W8*60000) | Y8: =IF(C8="","",IFERROR(U8*VLOOKUP(IF(L8="",Q8,L8),'13 Policy Matrix'!$A$4:$F$30,4,FALSE)+V8*VLOOKUP(IF(L8="",Q8,L8),'13 Policy Matrix'!$A$4:$F$30,5,FALSE)+W8*VLOOKUP(IF(L8="",Q8,L8),'13 Policy Matrix'!$A$4:$F$30,6,FALSE),0)) | Z8: =IF(C8="","",IF(U8+V8>=50,1000000,IF(U8+V8>=20,300000,IF(U8+V8>=10,100000,0)))+IF(W8>=100,300000,0)) | AA8: =IF(C8="","",Y8+Z8) | AB8: =IFERROR(S8/R8,0) -> 0 | AC8: =IFERROR((U8+V8)/T8,0) -> 0 | AE8: =IFERROR((U8+V8+W8)/AD8,0) -> 0
P9: =IF(C9="","",SUM(M9:O9)) | Q9: =IF(C9="","",IF((U9+V9)>=20,"Leader An Nhiên",IF((U9+V9)>=5,"Đại sứ Ban Mai",IF(P9>=10,"Affiliate cơ bản",IF(P9>=1,"Người Gieo Giọt Lành",""))))) | X9: =IF(C9="","",U9*199000+V9*249000+W9*60000) | Y9: =IF(C9="","",IFERROR(U9*VLOOKUP(IF(L9="",Q9,L9),'13 Policy Matrix'!$A$4:$F$30,4,FALSE)+V9*VLOOKUP(IF(L9="",Q9,L9),'13 Policy Matrix'!$A$4:$F$30,5,FALSE)+W9*VLOOKUP(IF(L9="",Q9,L9),'13 Policy Matrix'!$A$4:$F$30,6,FALSE),0)) | Z9: =IF(C9="","",IF(U9+V9>=50,1000000,IF(U9+V9>=20,300000,IF(U9+V9>=10,100000,0)))+IF(W9>=100,300000,0)) | AA9: =IF(C9="","",Y9+Z9) | AB9: =IFERROR(S9/R9,0) -> 0 | AC9: =IFERROR((U9+V9)/T9,0) -> 0 | AE9: =IFERROR((U9+V9+W9)/AD9,0) -> 0
P10: =IF(C10="","",SUM(M10:O10)) | Q10: =IF(C10="","",IF((U10+V10)>=20,"Leader An Nhiên",IF((U10+V10)>=5,"Đại sứ Ban Mai",IF(P10>=10,"Affiliate cơ bản",IF(P10>=1,"Người Gieo Giọt Lành",""))))) | X10: =IF(C10="","",U10*199000+V10*249000+W10*60000) | Y10: =IF(C10="","",IFERROR(U10*VLOOKUP(IF(L10="",Q10,L10),'13 Policy Matrix'!$A$4:$F$30,4,FALSE)+V10*VLOOKUP(IF(L10="",Q10,L10),'13 Policy Matrix'!$A$4:$F$30,5,FALSE)+W10*VLOOKUP(IF(L10="",Q10,L10),'13 Policy Matrix'!$A$4:$F$30,6,FALSE),0)) | Z10: =IF(C10="","",IF(U10+V10>=50,1000000,IF(U10+V10>=20,300000,IF(U10+V10>=10,100000,0)))+IF(W10>=100,300000,0)) | AA10: =IF(C10="","",Y10+Z10) | AB10: =IFERROR(S10/R10,0) -> 0 | AC10: =IFERROR((U10+V10)/T10,0) -> 0 | AE10: =IFERROR((U10+V10+W10)/AD10,0) -> 0
P11: =IF(C11="","",SUM(M11:O11)) | Q11: =IF(C11="","",IF((U11+V11)>=20,"Leader An Nhiên",IF((U11+V11)>=5,"Đại sứ Ban Mai",IF(P11>=10,"Affiliate cơ bản",IF(P11>=1,"Người Gieo Giọt Lành",""))))) | X11: =IF(C11="","",U11*199000+V11*249000+W11*60000) | Y11: =IF(C11="","",IFERROR(U11*VLOOKUP(IF(L11="",Q11,L11),'13 Policy Matrix'!$A$4:$F$30,4,FALSE)+V11*VLOOKUP(IF(L11="",Q11,L11),'13 Policy Matrix'!$A$4:$F$30,5,FALSE)+W11*VLOOKUP(IF(L11="",Q11,L11),'13 Policy Matrix'!$A$4:$F$30,6,FALSE),0)) | Z11: =IF(C11="","",IF(U11+V11>=50,1000000,IF(U11+V11>=20,300000,IF(U11+V11>=10,100000,0)))+IF(W11>=100,300000,0)) | AA11: =IF(C11="","",Y11+Z11) | AB11: =IFERROR(S11/R11,0) -> 0 | AC11: =IFERROR((U11+V11)/T11,0) -> 0 | AE11: =IFERROR((U11+V11+W11)/AD11,0) -> 0
P12: =IF(C12="","",SUM(M12:O12)) | Q12: =IF(C12="","",IF((U12+V12)>=20,"Leader An Nhiên",IF((U12+V12)>=5,"Đại sứ Ban Mai",IF(P12>=10,"Affiliate cơ bản",IF(P12>=1,"Người Gieo Giọt Lành",""))))) | X12: =IF(C12="","",U12*199000+V12*249000+W12*60000) | Y12: =IF(C12="","",IFERROR(U12*VLOOKUP(IF(L12="",Q12,L12),'13 Policy Matrix'!$A$4:$F$30,4,FALSE)+V12*VLOOKUP(IF(L12="",Q12,L12),'13 Policy Matrix'!$A$4:$F$30,5,FALSE)+W12*VLOOKUP(IF(L12="",Q12,L12),'13 Policy Matrix'!$A$4:$F$30,6,FALSE),0)) | Z12: =IF(C12="","",IF(U12+V12>=50,1000000,IF(U12+V12>=20,300000,IF(U12+V12>=10,100000,0)))+IF(W12>=100,300000,0)) | AA12: =IF(C12="","",Y12+Z12) | AB12: =IFERROR(S12/R12,0) -> 0 | AC12: =IFERROR((U12+V12)/T12,0) -> 0 | AE12: =IFERROR((U12+V12+W12)/AD12,0) -> 0
P13: =IF(C13="","",SUM(M13:O13)) | Q13: =IF(C13="","",IF((U13+V13)>=20,"Leader An Nhiên",IF((U13+V13)>=5,"Đại sứ Ban Mai",IF(P13>=10,"Affiliate cơ bản",IF(P13>=1,"Người Gieo Giọt Lành",""))))) | X13: =IF(C13="","",U13*199000+V13*249000+W13*60000) | Y13: =IF(C13="","",IFERROR(U13*VLOOKUP(IF(L13="",Q13,L13),'13 Policy Matrix'!$A$4:$F$30,4,FALSE)+V13*VLOOKUP(IF(L13="",Q13,L13),'13 Policy Matrix'!$A$4:$F$30,5,FALSE)+W13*VLOOKUP(IF(L13="",Q13,L13),'13 Policy Matrix'!$A$4:$F$30,6,FALSE),0)) | Z13: =IF(C13="","",IF(U13+V13>=50,1000000,IF(U13+V13>=20,300000,IF(U13+V13>=10,100000,0)))+IF(W13>=100,300000,0)) | AA13: =IF(C13="","",Y13+Z13) | AB13: =IFERROR(S13/R13,0) -> 0 | AC13: =IFERROR((U13+V13)/T13,0) -> 0 | AE13: =IFERROR((U13+V13+W13)/AD13,0) -> 0
P14: =IF(C14="","",SUM(M14:O14)) | Q14: =IF(C14="","",IF((U14+V14)>=20,"Leader An Nhiên",IF((U14+V14)>=5,"Đại sứ Ban Mai",IF(P14>=10,"Affiliate cơ bản",IF(P14>=1,"Người Gieo Giọt Lành",""))))) | X14: =IF(C14="","",U14*199000+V14*249000+W14*60000) | Y14: =IF(C14="","",IFERROR(U14*VLOOKUP(IF(L14="",Q14,L14),'13 Policy Matrix'!$A$4:$F$30,4,FALSE)+V14*VLOOKUP(IF(L14="",Q14,L14),'13 Policy Matrix'!$A$4:$F$30,5,FALSE)+W14*VLOOKUP(IF(L14="",Q14,L14),'13 Policy Matrix'!$A$4:$F$30,6,FALSE),0)) | Z14: =IF(C14="","",IF(U14+V14>=50,1000000,IF(U14+V14>=20,300000,IF(U14+V14>=10,100000,0)))+IF(W14>=100,300000,0)) | AA14: =IF(C14="","",Y14+Z14) | AB14: =IFERROR(S14/R14,0) -> 0 | AC14: =IFERROR((U14+V14)/T14,0) -> 0 | AE14: =IFERROR((U14+V14+W14)/AD14,0) -> 0
P15: =IF(C15="","",SUM(M15:O15)) | Q15: =IF(C15="","",IF((U15+V15)>=20,"Leader An Nhiên",IF((U15+V15)>=5,"Đại sứ Ban Mai",IF(P15>=10,"Affiliate cơ bản",IF(P15>=1,"Người Gieo Giọt Lành",""))))) | X15: =IF(C15="","",U15*199000+V15*249000+W15*60000) | Y15: =IF(C15="","",IFERROR(U15*VLOOKUP(IF(L15="",Q15,L15),'13 Policy Matrix'!$A$4:$F$30,4,FALSE)+V15*VLOOKUP(IF(L15="",Q15,L15),'13 Policy Matrix'!$A$4:$F$30,5,FALSE)+W15*VLOOKUP(IF(L15="",Q15,L15),'13 Policy Matrix'!$A$4:$F$30,6,FALSE),0)) | Z15: =IF(C15="","",IF(U15+V15>=50,1000000,IF(U15+V15>=20,300000,IF(U15+V15>=10,100000,0)))+IF(W15>=100,300000,0)) | AA15: =IF(C15="","",Y15+Z15) | AB15: =IFERROR(S15/R15,0) -> 0 | AC15: =IFERROR((U15+V15)/T15,0) -> 0 | AE15: =IFERROR((U15+V15+W15)/AD15,0) -> 0
P16: =IF(C16="","",SUM(M16:O16)) | Q16: =IF(C16="","",IF((U16+V16)>=20,"Leader An Nhiên",IF((U16+V16)>=5,"Đại sứ Ban Mai",IF(P16>=10,"Affiliate cơ bản",IF(P16>=1,"Người Gieo Giọt Lành",""))))) | X16: =IF(C16="","",U16*199000+V16*249000+W16*60000) | Y16: =IF(C16="","",IFERROR(U16*VLOOKUP(IF(L16="",Q16,L16),'13 Policy Matrix'!$A$4:$F$30,4,FALSE)+V16*VLOOKUP(IF(L16="",Q16,L16),'13 Policy Matrix'!$A$4:$F$30,5,FALSE)+W16*VLOOKUP(IF(L16="",Q16,L16),'13 Policy Matrix'!$A$4:$F$30,6,FALSE),0)) | Z16: =IF(C16="","",IF(U16+V16>=50,1000000,IF(U16+V16>=20,300000,IF(U16+V16>=10,100000,0)))+IF(W16>=100,300000,0)) | AA16: =IF(C16="","",Y16+Z16) | AB16: =IFERROR(S16/R16,0) -> 0 | AC16: =IFERROR((U16+V16)/T16,0) -> 0 | AE16: =IFERROR((U16+V16+W16)/AD16,0) -> 0
P17: =IF(C17="","",SUM(M17:O17)) | Q17: =IF(C17="","",IF((U17+V17)>=20,"Leader An Nhiên",IF((U17+V17)>=5,"Đại sứ Ban Mai",IF(P17>=10,"Affiliate cơ bản",IF(P17>=1,"Người Gieo Giọt Lành",""))))) | X17: =IF(C17="","",U17*199000+V17*249000+W17*60000) | Y17: =IF(C17="","",IFERROR(U17*VLOOKUP(IF(L17="",Q17,L17),'13 Policy Matrix'!$A$4:$F$30,4,FALSE)+V17*VLOOKUP(IF(L17="",Q17,L17),'13 Policy Matrix'!$A$4:$F$30,5,FALSE)+W17*VLOOKUP(IF(L17="",Q17,L17),'13 Policy Matrix'!$A$4:$F$30,6,FALSE),0)) | Z17: =IF(C17="","",IF(U17+V17>=50,1000000,IF(U17+V17>=20,300000,IF(U17+V17>=10,100000,0)))+IF(W17>=100,300000,0)) | AA17: =IF(C17="","",Y17+Z17) | AB17: =IFERROR(S17/R17,0) -> 0 | AC17: =IFERROR((U17+V17)/T17,0) -> 0 | AE17: =IFERROR((U17+V17+W17)/AD17,0) -> 0
